Traceback (most recent call last):
  File "C:\Users\U\anaconda3\envs\MLOps_env\lib\site-packages\wandb\sdk\wandb_config.py", line 165, in __getattr__
    return self.__getitem__(key)
  File "C:\Users\U\anaconda3\envs\MLOps_env\lib\site-packages\wandb\sdk\wandb_config.py", line 130, in __getitem__
    return self._items[key]
KeyError: 'batch_size'

The above exception was the direct cause of the following exception:

Traceback (most recent call last):
  File "c:\Users\U\Desktop\Wine Quality Prediction\src\train\train.py", line 74, in train_NN
    train_dataset, batch_size=config.batch_size, shuffle=True)
  File "C:\Users\U\anaconda3\envs\MLOps_env\lib\site-packages\wandb\sdk\wandb_config.py", line 167, in __getattr__
    raise AttributeError(
AttributeError: <class 'wandb.sdk.wandb_config.Config'> object has no attribute 'batch_size'
